Workbook

Sheet Lisez-moi
A1: MON HEROS — Systeme de jeu (maths) v1.0
A2: Classeur de game design pour l'app get-fit. Toute la balance du RPG dans un seul fichier.
A5: PRINCIPE DIRECTEUR
A6: 1. L'entrainement est le moteur. | B6: On peut atteindre le niveau max sans jamais logger un repas.
A7: 2. La nutrition est un accelerateur. | B7: Elle multiplie l'XP gagne et augmente la Chance. Elle ne debloque rien d'exclusif.
A8: 3. La penalite est douce et reversible. | B8: Le Moral baisse, jamais le niveau. Aucune perte d'objet ni de progres acquis.
A9: 4. Le donjon porte la boucle courte. | B9: Il tourne tout seul, donne du loot chaque jour, et se durcit a chaque cycle.
A10: 5. Le rythme est cale sur la vraie vie. | B10: Tout est dimensionne pour 4 seances/semaine. Pas de farm possible sans entrainement reel.
A12: COMMENT LIRE CE CLASSEUR
A13: Cellules JAUNES avec texte BLEU | B13: -> leviers a ajuster. Ce sont les seules cellules a modifier.
A14: Texte NOIR | B14: -> formule calculee. Ne pas ecraser.
A15: Texte VERT | B15: -> lien vers un autre onglet.
A17: ONGLETS
A18: Parametres | B18: Tous les leviers du jeu au meme endroit. Point de depart de chaque ajustement.
A19: Progression | B19: Courbe XP niveau 1 a 50, stats du personnage, gemmes, temps reel estime.
A20: XP Seance | B20: Comment une vraie seance se convertit en XP. Exemples chiffres.
A21: Nutrition-Moral | B21: Score nutritionnel quotidien, multiplicateur XP, systeme de Moral et penalites.
A22: Donjon | B22: PV/ATQ des ennemis par palier et par cycle, boss, or et essence largues.
A23: Sim Combat | B23: Resout un combat joueur vs palier. Sert a verifier qu'un niveau donne passe ou casse.
A24: Equipement | B24: 6 emplacements, 5 raretes, puissance des objets, couts de forge.
A25: Loot-Pity | B25: Taux de drop, effet de la Chance, systeme anti-malchance (pity doux + dur).
A26: Economie | B26: Revenus et depenses des 3 monnaies : Or, Essence, Gemmes.
A27: Sim 52 semaines | B27: Projection an 1 : niveau, cycle de donjon, monnaies, semaine par semaine.
A29: SOURCES CONSULTEES POUR LA BALANCE
A30: Courbe XP polynomiale, exposant 1,5-2,2 | B30: jaconir.online — RPG XP Curves Explained (exposant >2,5 = mur infranchissable)
A31: Soft cap apres un niveau palier | B31: meme source — evite le mur de fin de partie
A32: Ennemi ~2x le joueur, boss ~5x PV | B32: forums.rpgmakerweb.com — Balancing enemy stats, gold, exp
A33: Plafonner le pire cas de malchance (pity) | B33: gamedeveloper.com — Emotions and Randomness: Loot Drops
A34: Pity dur type Granblue/Genshin | B34: arxiv.org 2208.03602 — Gacha Game: Prospect Theory Meets Optimal Pricing
A35: Reussite le jour 1 = +64% de retention | B35: guul.games / donnees plateforme Trophy — gamification fitness
A36: Streaks = mecanique de retention #1 | B36: trophy.so — etude de cas Streaks
A37: Rendements decroissants sur stats tardives | B37: gamescrye.com — 5 Tips for Balancing an RPG Game
A39: AVERTISSEMENT
A40: Je suis un assistant IA, pas un professionnel de la sante. | B40: Consulte ton medecin de famille avant d'entreprendre un nouveau regime.
A42: RESULTAT DE LA BALANCE (rythme 4 seances/semaine)
A43: Niveau 5 | B43: 1 semaine — l'accroche : une victoire des la premiere semaine.
A44: Niveau 10 | B44: 1,7 mois — le donjon tourne, l'equipement commence a compter.
A45: Niveau 20 | B45: 10 mois — cycle 8 du donjon, epique bien forge.
A46: Niveau 25 | B46: 1 an et demi — soft cap, la courbe s'aplatit.
A47: Niveau 50 | B47: horizon pluriannuel, volontairement. C'est une app de vie, pas une saison.
...

Sheet Parametres
A1: PARAMETRES — tous les leviers du jeu
A2: Modifie uniquement les cellules jaunes. Tout le reste du classeur s'ajuste automatiquement.
A4: XP & COURBE DE NIVEAU
A5: XP de base par seance | B5: 50 | C5: XP | D5: Recompense de presence : tu t'es rendu au gym.
A6: Diviseur de volume | B6: 200 | C6: lb/XP | D6: Volume total (poids x reps x series) divise par ce chiffre.
A7: Bonus par record personnel (PR) | B7: 25 | C7: XP | D7: Recompense le progres reel, pas juste la repetition.
A8: Coefficient courbe XP | B8: 50 | D8: XP requis = coeff x niveau^exposant
A9: Exposant courbe XP | B9: 1.5 | D9: 1,5 = standard RPG. >2,5 cree un mur (source: jaconir).
A10: Niveau du soft cap | B10: 25 | C10: niv | D10: Au-dela, la courbe devient lineaire au lieu d'exploser.
A11: Increment lineaire apres soft cap | B11: 200 | C11: XP | D11: Cout ajoute par niveau apres le soft cap. Bas volontairement : le niv. 50 doit rester atteignable.
A12: Niveau maximum | B12: 50 | C12: niv | D12: Horizon long terme volontairement pluriannuel.
A14: STATS DU PERSONNAGE
A15: PV de base | B15: 100 | C15: PV | D15: Niveau 1.
A16: PV par niveau | B16: 35 | C16: PV | D16: Croissance lineaire = previsible. Calibre pour survivre a une run complete.
A17: ATQ de base | B17: 10 | C17: ATQ
A18: ATQ par niveau | B18: 6 | C18: ATQ | D18: Calibre pour tuer le boss en ~12 tours a niveau approprie.
A19: DEF de base | B19: 5 | C19: DEF
A20: DEF par niveau | B20: 2.5 | C20: DEF
A21: Critique de base | B21: 0.05 | C21: % | D21: 5% au niveau 1.
A22: Gain de critique maximal | B22: 0.15 | C22: % | D22: Plafond du gain lie au niveau : +15 points max.
A23: Constante K du critique | B23: 20 | D23: crit = base + max x niv/(niv+K). Rendements decroissants.
A24: Multiplicateur de coup critique | B24: 1.75 | C24: x
A25: Constante d'armure | B25: 80 | D25: reduction = DEF/(DEF+K). Jamais de degats negatifs, rendements decroissants.
A26: Regeneration entre paliers | B26: 0.25 | C26: % PV max | D26: % des PV max recuperes apres chaque palier. Calibre pour que le BOSS soit le vrai combat.
A27: NUTRITION
A28: Bonus XP — calories dans la cible | B28: 0.05 | C28: % | D28: Cible +/- 10%. Independant des 2 autres.
A29: Bonus XP — proteines atteintes | B29: 0.08 | C29: % | D29: Au moins 90% de la cible. Le plus eleve : coherent avec un style riche en proteines.
A30: Bonus XP — eau atteinte | B30: 0.04 | C30: % | D30: Au moins 90% de la cible.
A31: Bonus XP par jour de serie (2+ cibles) | B31: 0.01 | C31: % | D31: Un jour compte pour la serie des que 2 des 3 cibles sont atteintes.
A32: Bonus XP de serie — maximum | B32: 0.15 | C32: % | D32: Plafond a 15 jours de serie consecutifs (2+ cibles/jour).
A33: Chance par jour de serie nutri | B33: 2 | C33: pts | D33: Meme compteur de serie que le bonus XP.
A34: Chance maximale (nutrition) | B34: 30 | C34: pts | D34: Plafond a 15 jours (meme fenetre que le bonus XP).
A35: Bonus XP par jour de serie | B35: 0.01 | C35: % | D35: S'accumule tant que les jours 'reussis' s'enchainent.
A36: MORAL & PENALITES | B36: 0.15 | C36: % | D36: Plafond a 15 jours de serie.
A37: Moral maximum | B37: 100 | C37: pts | D37: Depart a 100.
A38: Moral — seance loggee | B38: 8 | C38: pts
A39: Moral — seance prevue manquee | B39: -10 | C39: pts | D39: Seule source de penalite du jeu. La nutrition n'affecte jamais le moral.
A40: Multiplicateur XP a moral 0 | B40: 0.85 | C40: x | D40: Plancher : -15% max. Jamais de spirale.
A41: Seuil de moral plein | B41: 80 | C41: pts | D41: Au-dessus, aucun malus. Deux bonnes seances suffisent a y remonter.
A42: Moral — seance loggee | B42: 8 | C42: pts
...

Sheet Progression
A1: PROGRESSION — courbe XP, stats et temps reel estime
A2: XP requis = coefficient x niveau^exposant, puis lineaire apres le soft cap (evite le mur de fin de partie). Stats PV/ATQ/DEF lineaires = previsibles ; critique a rendements decroissants.
A4: Niveau | B4: XP requis (du niv. precedent) | C4: XP cumulatif | D4: PV | E4: ATQ | F4: DEF | G4: Critique | H4: Gemmes gagnees | I4: Gemmes cumulees | J4: Seances cumulees | K4: Semaines estimees | L4: Mois estimes | M4: Jalon
A5: 1 | B5: =IF(A5=1,0,IF(A5-1<=Parametres!$B$10,ROUND(Parametres!$B$8*(A5-1)^Parametres!$B$9,0),ROUND(Parametres!$B$8*Parametres!$B$10^Parametres!$B$9+Parametres!$B$11*(A5-1-Parametres!$B$10),0))) -> 0 | C5: =B5 -> 0 | D5: =Parametres!$B$15+Parametres!$B$16*(A5-1) -> 100 | E5: =Parametres!$B$17+Parametres!$B$18*(A5-1) -> 10 | F5: =Parametres!$B$19+Parametres!$B$20*(A5-1) -> 5 | G5: =Parametres!$B$21+Parametres!$B$22*(A5/(A5+Parametres!$B$23)) -> 0.057142857 | H5: =IF(A5=1,0,Parametres!$B$70+Parametres!$B$71*INT(A5/5)) -> 0 | I5: =H5 -> 0 | J5: =ROUND(C5/Parametres!$B$104,0) -> 0 | K5: =ROUND(J5/Parametres!$B$46,1) -> 0 | L5: =ROUND(K5/4.345,1) -> 0 | M5: Depart
A6: 2 | B6: =IF(A6=1,0,IF(A6-1<=Parametres!$B$10,ROUND(Parametres!$B$8*(A6-1)^Parametres!$B$9,0),ROUND(Parametres!$B$8*Parametres!$B$10^Parametres!$B$9+Parametres!$B$11*(A6-1-Parametres!$B$10),0))) -> 50 | C6: =C5+B6 -> 50 | D6: =Parametres!$B$15+Parametres!$B$16*(A6-1) -> 135 | E6: =Parametres!$B$17+Parametres!$B$18*(A6-1) -> 16 | F6: =Parametres!$B$19+Parametres!$B$20*(A6-1) -> 7.5 | G6: =Parametres!$B$21+Parametres!$B$22*(A6/(A6+Parametres!$B$23)) -> 0.063636364 | H6: =IF(A6=1,0,Parametres!$B$70+Parametres!$B$71*INT(A6/5)) -> 3 | I6: =I5+H6 -> 3 | J6: =ROUND(C6/Parametres!$B$104,0) -> 0 | K6: =ROUND(J6/Parametres!$B$46,1) -> 0 | L6: =ROUND(K6/4.345,1) -> 0
A7: 3 | B7: =IF(A7=1,0,IF(A7-1<=Parametres!$B$10,ROUND(Parametres!$B$8*(A7-1)^Parametres!$B$9,0),ROUND(Parametres!$B$8*Parametres!$B$10^Parametres!$B$9+Parametres!$B$11*(A7-1-Parametres!$B$10),0))) -> 141 | C7: =C6+B7 -> 191 | D7: =Parametres!$B$15+Parametres!$B$16*(A7-1) -> 170 | E7: =Parametres!$B$17+Parametres!$B$18*(A7-1) -> 22 | F7: =Parametres!$B$19+Parametres!$B$20*(A7-1) -> 10 | G7: =Parametres!$B$21+Parametres!$B$22*(A7/(A7+Parametres!$B$23)) -> 0.069565217 | H7: =IF(A7=1,0,Parametres!$B$70+Parametres!$B$71*INT(A7/5)) -> 3 | I7: =I6+H7 -> 6 | J7: =ROUND(C7/Parametres!$B$104,0) -> 1 | K7: =ROUND(J7/Parametres!$B$46,1) -> 0.3 | L7: =ROUND(K7/4.345,1) -> 0.1 | M7: Premier equipement
A8: 4 | B8: =IF(A8=1,0,IF(A8-1<=Parametres!$B$10,ROUND(Parametres!$B$8*(A8-1)^Parametres!$B$9,0),ROUND(Parametres!$B$8*Parametres!$B$10^Parametres!$B$9+Parametres!$B$11*(A8-1-Parametres!$B$10),0))) -> 260 | C8: =C7+B8 -> 451 | D8: =Parametres!$B$15+Parametres!$B$16*(A8-1) -> 205 | E8: =Parametres!$B$17+Parametres!$B$18*(A8-1) -> 28 | F8: =Parametres!$B$19+Parametres!$B$20*(A8-1) -> 12.5 | G8: =Parametres!$B$21+Parametres!$B$22*(A8/(A8+Parametres!$B$23)) -> 0.075 | H8: =IF(A8=1,0,Parametres!$B$70+Parametres!$B$71*INT(A8/5)) -> 3 | I8: =I7+H8 -> 9 | J8: =ROUND(C8/Parametres!$B$104,0) -> 2 | K8: =ROUND(J8/Parametres!$B$46,1) -> 0.5 | L8: =ROUND(K8/4.345,1) -> 0.1
A9: 5 | B9: =IF(A9=1,0,IF(A9-1<=Parametres!$B$10,ROUND(Parametres!$B$8*(A9-1)^Parametres!$B$9,0),ROUND(Parametres!$B$8*Parametres!$B$10^Parametres!$B$9+Parametres!$B$11*(A9-1-Parametres!$B$10),0))) -> 400 | C9: =C8+B9 -> 851 | D9: =Parametres!$B$15+Parametres!$B$16*(A9-1) -> 240 | E9: =Parametres!$B$17+Parametres!$B$18*(A9-1) -> 34 | F9: =Parametres!$B$19+Parametres!$B$20*(A9-1) -> 15 | G9: =Parametres!$B$21+Parametres!$B$22*(A9/(A9+Parametres!$B$23)) -> 0.08 | H9: =IF(A9=1,0,Parametres!$B$70+Parametres!$B$71*INT(A9/5)) -> 4 | I9: =I8+H9 -> 13 | J9: =ROUND(C9/Parametres!$B$104,0) -> 4 | K9: =ROUND(J9/Parametres!$B$46,1) -> 1 | L9: =ROUND(K9/4.345,1) -> 0.2 | M9: Donjon debloque
A10: 6 | B10: =IF(A10=1,0,IF(A10-1<=Parametres!$B$10,ROUND(Parametres!$B$8*(A10-1)^Parametres!$B$9,0),ROUND(Parametres!$B$8*Parametres!$B$10^Parametres!$B$9+Parametres!$B$11*(A10-1-Parametres!$B$10),0))) -> 559 | C10: =C9+B10 -> 1410 | D10: =Parametres!$B$15+Parametres!$B$16*(A10-1) -> 275 | E10: =Parametres!$B$17+Parametres!$B$18*(A10-1) -> 40 | F10: =Parametres!$B$19+Parametres!$B$20*(A10-1) -> 17.5 | G10: =Parametres!$B$21+Parametres!$B$22*(A10/(A10+Parametres!$B$23)) -> 0.084615385 | H10: =IF(A10=1,0,Parametres!$B$70+Parametres!$B$71*INT(A10/5)) -> 4 | I10: =I9+H10 -> 17 | J10: =ROUND(C10/Parametres!$B$104,0) -> 7 | K10: =ROUND(J10/Parametres!$B$46,1) -> 1.8 | L10: =ROUND(K10/4.345,1) -> 0.4
A11: 7 | B11: =IF(A11=1,0,IF(A11-1<=Parametres!$B$10,ROUND(Parametres!$B$8*(A11-1)^Parametres!$B$9,0),ROUND(Parametres!$B$8*Parametres!$B$10^Parametres!$B$9+Parametres!$B$11*(A11-1-Parametres!$B$10),0))) -> 735 | C11: =C10+B11 -> 2145 | D11: =Parametres!$B$15+Parametres!$B$16*(A11-1) -> 310 | E11: =Parametres!$B$17+Parametres!$B$18*(A11-1) -> 46 | F11: =Parametres!$B$19+Parametres!$B$20*(A11-1) -> 20 | G11: =Parametres!$B$21+Parametres!$B$22*(A11/(A11+Parametres!$B$23)) -> 0.088888889 | H11: =IF(A11=1,0,Parametres!$B$70+Parametres!$B$71*INT(A11/5)) -> 4 | I11: =I10+H11 -> 21 | J11: =ROUND(C11/Parametres!$B$104,0) -> 11 | K11: =ROUND(J11/Parametres!$B$46,1) -> 2.8 | L11: =ROUND(K11/4.345,1) -> 0.6
A12: 8 | B12: =IF(A12=1,0,IF(A12-1<=Parametres!$B$10,ROUND(Parametres!$B$8*(A12-1)^Parametres!$B$9,0),ROUND(Parametres!$B$8*Parametres!$B$10^Parametres!$B$9+Parametres!$B$11*(A12-1-Parametres!$B$10),0))) -> 926 | C12: =C11+B12 -> 3071 | D12: =Parametres!$B$15+Parametres!$B$16*(A12-1) -> 345 | E12: =Parametres!$B$17+Parametres!$B$18*(A12-1) -> 52 | F12: =Parametres!$B$19+Parametres!$B$20*(A12-1) -> 22.5 | G12: =Parametres!$B$21+Parametres!$B$22*(A12/(A12+Parametres!$B$23)) -> 0.092857143 | H12: =IF(A12=1,0,Parametres!$B$70+Parametres!$B$71*INT(A12/5)) -> 4 | I12: =I11+H12 -> 25 | J12: =ROUND(C12/Parametres!$B$104,0) -> 16 | K12: =ROUND(J12/Parametres!$B$46,1) -> 4 | L12: =ROUND(K12/4.345,1) -> 0.9
A13: 9 | B13: =IF(A13=1,0,IF(A13-1<=Parametres!$B$10,ROUND(Parametres!$B$8*(A13-1)^Parametres!$B$9,0),ROUND(Parametres!$B$8*Parametres!$B$10^Parametres!$B$9+Parametres!$B$11*(A13-1-Parametres!$B$10),0))) -> 1131 | C13: =C12+B13 -> 4202 | D13: =Parametres!$B$15+Parametres!$B$16*(A13-1) -> 380 | E13: =Parametres!$B$17+Parametres!$B$18*(A13-1) -> 58 | F13: =Parametres!$B$19+Parametres!$B$20*(A13-1) -> 25 | G13: =Parametres!$B$21+Parametres!$B$22*(A13/(A13+Parametres!$B$23)) -> 0.096551724 | H13: =IF(A13=1,0,Parametres!$B$70+Parametres!$B$71*INT(A13/5)) -> 4 | I13: =I12+H13 -> 29 | J13: =ROUND(C13/Parametres!$B$104,0) -> 22 | K13: =ROUND(J13/Parametres!$B$46,1) -> 5.5 | L13: =ROUND(K13/4.345,1) -> 1.3
A14: 10 | B14: =IF(A14=1,0,IF(A14-1<=Parametres!$B$10,ROUND(Parametres!$B$8*(A14-1)^Parametres!$B$9,0),ROUND(Parametres!$B$8*Parametres!$B$10^Parametres!$B$9+Parametres!$B$11*(A14-1-Parametres!$B$10),0))) -> 1350 | C14: =C13+B14 -> 5552 | D14: =Parametres!$B$15+Parametres!$B$16*(A14-1) -> 415 | E14: =Parametres!$B$17+Parametres!$B$18*(A14-1) -> 64 | F14: =Parametres!$B$19+Parametres!$B$20*(A14-1) -> 27.5 | G14: =Parametres!$B$21+Parametres!$B$22*(A14/(A14+Parametres!$B$23)) -> 0.1 | H14: =IF(A14=1,0,Parametres!$B$70+Parametres!$B$71*INT(A14/5)) -> 5 | I14: =I13+H14 -> 34 | J14: =ROUND(C14/Parametres!$B$104,0) -> 29 | K14: =ROUND(J14/Parametres!$B$46,1) -> 7.3 | L14: =ROUND(K14/4.345,1) -> 1.7 | M14: Cycle 2 accessible
A15: 11 | B15: =IF(A15=1,0,IF(A15-1<=Parametres!$B$10,ROUND(Parametres!$B$8*(A15-1)^Parametres!$B$9,0),ROUND(Parametres!$B$8*Parametres!$B$10^Parametres!$B$9+Parametres!$B$11*(A15-1-Parametres!$B$10),0))) -> 1581 | C15: =C14+B15 -> 7133 | D15: =Parametres!$B$15+Parametres!$B$16*(A15-1) -> 450 | E15: =Parametres!$B$17+Parametres!$B$18*(A15-1) -> 70 | F15: =Parametres!$B$19+Parametres!$B$20*(A15-1) -> 30 | G15: =Parametres!$B$21+Parametres!$B$22*(A15/(A15+Parametres!$B$23)) -> 0.10322581 | H15: =IF(A15=1,0,Parametres!$B$70+Parametres!$B$71*INT(A15/5)) -> 5 | I15: =I14+H15 -> 39 | J15: =ROUND(C15/Parametres!$B$104,0) -> 37 | K15: =ROUND(J15/Parametres!$B$46,1) -> 9.3 | L15: =ROUND(K15/4.345,1) -> 2.1
A16: 12 | B16: =IF(A16=1,0,IF(A16-1<=Parametres!$B$10,ROUND(Parametres!$B$8*(A16-1)^Parametres!$B$9,0),ROUND(Parametres!$B$8*Parametres!$B$10^Parametres!$B$9+Parametres!$B$11*(A16-1-Parametres!$B$10),0))) -> 1824 | C16: =C15+B16 -> 8957 | D16: =Parametres!$B$15+Parametres!$B$16*(A16-1) -> 485 | E16: =Parametres!$B$17+Parametres!$B$18*(A16-1) -> 76 | F16: =Parametres!$B$19+Parametres!$B$20*(A16-1) -> 32.5 | G16: =Parametres!$B$21+Parametres!$B$22*(A16/(A16+Parametres!$B$23)) -> 0.10625 | H16: =IF(A16=1,0,Parametres!$B$70+Parametres!$B$71*INT(A16/5)) -> 5 | I16: =I15+H16 -> 44 | J16: =ROUND(C16/Parametres!$B$104,0) -> 46 | K16: =ROUND(J16/Parametres!$B$46,1) -> 11.5 | L16: =ROUND(K16/4.345,1) -> 2.6
A17: 13 | B17: =IF(A17=1,0,IF(A17-1<=Parametres!$B$10,ROUND(Parametres!$B$8*(A17-1)^Parametres!$B$9,0),ROUND(Parametres!$B$8*Parametres!$B$10^Parametres!$B$9+Parametres!$B$11*(A17-1-Parametres!$B$10),0))) -> 2078 | C17: =C16+B17 -> 11035 | D17: =Parametres!$B$15+Parametres!$B$16*(A17-1) -> 520 | E17: =Parametres!$B$17+Parametres!$B$18*(A17-1) -> 82 | F17: =Parametres!$B$19+Parametres!$B$20*(A17-1) -> 35 | G17: =Parametres!$B$21+Parametres!$B$22*(A17/(A17+Parametres!$B$23)) -> 0.10909091 | H17: =IF(A17=1,0,Parametres!$B$70+Parametres!$B$71*INT(A17/5)) -> 5 | I17: =I16+H17 -> 49 | J17: =ROUND(C17/Parametres!$B$104,0) -> 57 | K17: =ROUND(J17/Parametres!$B$46,1) -> 14.3 | L17: =ROUND(K17/4.345,1) -> 3.3
A18: 14 | B18: =IF(A18=1,0,IF(A18-1<=Parametres!$B$10,ROUND(Parametres!$B$8*(A18-1)^Parametres!$B$9,0),ROUND(Parametres!$B$8*Parametres!$B$10^Parametres!$B$9+Parametres!$B$11*(A18-1-Parametres!$B$10),0))) -> 2344 | C18: =C17+B18 -> 13379 | D18: =Parametres!$B$15+Parametres!$B$16*(A18-1) -> 555 | E18: =Parametres!$B$17+Parametres!$B$18*(A18-1) -> 88 | F18: =Parametres!$B$19+Parametres!$B$20*(A18-1) -> 37.5 | G18: =Parametres!$B$21+Parametres!$B$22*(A18/(A18+Parametres!$B$23)) -> 0.11176471 | H18: =IF(A18=1,0,Parametres!$B$70+Parametres!$B$71*INT(A18/5)) -> 5 | I18: =I17+H18 -> 54 | J18: =ROUND(C18/Parametres!$B$104,0) -> 69 | K18: =ROUND(J18/Parametres!$B$46,1) -> 17.3 | L18: =ROUND(K18/4.345,1) -> 4
A19: 15 | B19: =IF(A19=1,0,IF(A19-1<=Parametres!$B$10,ROUND(Parametres!$B$8*(A19-1)^Parametres!$B$9,0),ROUND(Parametres!$B$8*Parametres!$B$10^Parametres!$B$9+Parametres!$B$11*(A19-1-Parametres!$B$10),0))) -> 2619 | C19: =C18+B19 -> 15998 | D19: =Parametres!$B$15+Parametres!$B$16*(A19-1) -> 590 | E19: =Parametres!$B$17+Parametres!$B$18*(A19-1) -> 94 | F19: =Parametres!$B$19+Parametres!$B$20*(A19-1) -> 40 | G19: =Parametres!$B$21+Parametres!$B$22*(A19/(A19+Parametres!$B$23)) -> 0.11428571 | H19: =IF(A19=1,0,Parametres!$B$70+Parametres!$B$71*INT(A19/5)) -> 6 | I19: =I18+H19 -> 60 | J19: =ROUND(C19/Parametres!$B$104,0) -> 83 | K19: =ROUND(J19/Parametres!$B$46,1) -> 20.8 | L19: =ROUND(K19/4.345,1) -> 4.8 | M19: Coffres legendaires viables
A20: 16 | B20: =IF(A20=1,0,IF(A20-1<=Parametres!$B$10,ROUND(Parametres!$B$8*(A20-1)^Parametres!$B$9,0),ROUND(Parametres!$B$8*Parametres!$B$10^Parametres!$B$9+Parametres!$B$11*(A20-1-Parametres!$B$10),0))) -> 2905 | C20: =C19+B20 -> 18903 | D20: =Parametres!$B$15+Parametres!$B$16*(A20-1) -> 625 | E20: =Parametres!$B$17+Parametres!$B$18*(A20-1) -> 100 | F20: =Parametres!$B$19+Parametres!$B$20*(A20-1) -> 42.5 | G20: =Parametres!$B$21+Parametres!$B$22*(A20/(A20+Parametres!$B$23)) -> 0.11666667 | H20: =IF(A20=1,0,Parametres!$B$70+Parametres!$B$71*INT(A20/5)) -> 6 | I20: =I19+H20 -> 66 | J20: =ROUND(C20/Parametres!$B$104,0) -> 98 | K20: =ROUND(J20/Parametres!$B$46,1) -> 24.5 | L20: =ROUND(K20/4.345,1) -> 5.6
A21: 17 | B21: =IF(A21=1,0,IF(A21-1<=Parametres!$B$10,ROUND(Parametres!$B$8*(A21-1)^Parametres!$B$9,0),ROUND(Parametres!$B$8*Parametres!$B$10^Parametres!$B$9+Parametres!$B$11*(A21-1-Parametres!$B$10),0))) -> 3200 | C21: =C20+B21 -> 22103 | D21: =Parametres!$B$15+Parametres!$B$16*(A21-1) -> 660 | E21: =Parametres!$B$17+Parametres!$B$18*(A21-1) -> 106 | F21: =Parametres!$B$19+Parametres!$B$20*(A21-1) -> 45 | G21: =Parametres!$B$21+Parametres!$B$22*(A21/(A21+Parametres!$B$23)) -> 0.11891892 | H21: =IF(A21=1,0,Parametres!$B$70+Parametres!$B$71*INT(A21/5)) -> 6 | I21: =I20+H21 -> 72 | J21: =ROUND(C21/Parametres!$B$104,0) -> 115 | K21: =ROUND(J21/Parametres!$B$46,1) -> 28.8 | L21: =ROUND(K21/4.345,1) -> 6.6
A22: 18 | B22: =IF(A22=1,0,IF(A22-1<=Parametres!$B$10,ROUND(Parametres!$B$8*(A22-1)^Parametres!$B$9,0),ROUND(Parametres!$B$8*Parametres!$B$10^Parametres!$B$9+Parametres!$B$11*(A22-1-Parametres!$B$10),0))) -> 3505 | C22: =C21+B22 -> 25608 | D22: =Parametres!$B$15+Parametres!$B$16*(A22-1) -> 695 | E22: =Parametres!$B$17+Parametres!$B$18*(A22-1) -> 112 | F22: =Parametres!$B$19+Parametres!$B$20*(A22-1) -> 47.5 | G22: =Parametres!$B$21+Parametres!$B$22*(A22/(A22+Parametres!$B$23)) -> 0.12105263 | H22: =IF(A22=1,0,Parametres!$B$70+Parametres!$B$71*INT(A22/5)) -> 6 | I22: =I21+H22 -> 78 | J22: =ROUND(C22/Parametres!$B$104,0) -> 133 | K22: =ROUND(J22/Parametres!$B$46,1) -> 33.3 | L22: =ROUND(K22/4.345,1) -> 7.7
A23: 19 | B23: =IF(A23=1,0,IF(A23-1<=Parametres!$B$10,ROUND(Parametres!$B$8*(A23-1)^Parametres!$B$9,0),ROUND(Parametres!$B$8*Parametres!$B$10^Parametres!$B$9+Parametres!$B$11*(A23-1-Parametres!$B$10),0))) -> 3818 | C23: =C22+B23 -> 29426 | D23: =Parametres!$B$15+Parametres!$B$16*(A23-1) -> 730 | E23: =Parametres!$B$17+Parametres!$B$18*(A23-1) -> 118 | F23: =Parametres!$B$19+Parametres!$B$20*(A23-1) -> 50 | G23: =Parametres!$B$21+Parametres!$B$22*(A23/(A23+Parametres!$B$23)) -> 0.12307692 | H23: =IF(A23=1,0,Parametres!$B$70+Parametres!$B$71*INT(A23/5)) -> 6 | I23: =I22+H23 -> 84 | J23: =ROUND(C23/Parametres!$B$104,0) -> 152 | K23: =ROUND(J23/Parametres!$B$46,1) -> 38 | L23: =ROUND(K23/4.345,1) -> 8.7
A24: 20 | B24: =IF(A24=1,0,IF(A24-1<=Parametres!$B$10,ROUND(Parametres!$B$8*(A24-1)^Parametres!$B$9,0),ROUND(Parametres!$B$8*Parametres!$B$10^Parametres!$B$9+Parametres!$B$11*(A24-1-Parametres!$B$10),0))) -> 4141 | C24: =C23+B24 -> 33567 | D24: =Parametres!$B$15+Parametres!$B$16*(A24-1) -> 765 | E24: =Parametres!$B$17+Parametres!$B$18*(A24-1) -> 124 | F24: =Parametres!$B$19+Parametres!$B$20*(A24-1) -> 52.5 | G24: =Parametres!$B$21+Parametres!$B$22*(A24/(A24+Parametres!$B$23)) -> 0.125 | H24: =IF(A24=1,0,Parametres!$B$70+Parametres!$B$71*INT(A24/5)) -> 7 | I24: =I23+H24 -> 91 | J24: =ROUND(C24/Parametres!$B$104,0) -> 174 | K24: =ROUND(J24/Parametres!$B$46,1) -> 43.5 | L24: =ROUND(K24/4.345,1) -> 10
A25: 21 | B25: =IF(A25=1,0,IF(A25-1<=Parametres!$B$10,ROUND(Parametres!$B$8*(A25-1)^Parametres!$B$9,0),ROUND(Parametres!$B$8*Parametres!$B$10^Parametres!$B$9+Parametres!$B$11*(A25-1-Parametres!$B$10),0))) -> 4472 | C25: =C24+B25 -> 38039 | D25: =Parametres!$B$15+Parametres!$B$16*(A25-1) -> 800 | E25: =Parametres!$B$17+Parametres!$B$18*(A25-1) -> 130 | F25: =Parametres!$B$19+Parametres!$B$20*(A25-1) -> 55 | G25: =Parametres!$B$21+Parametres!$B$22*(A25/(A25+Parametres!$B$23)) -> 0.12682927 | H25: =IF(A25=1,0,Parametres!$B$70+Parametres!$B$71*INT(A25/5)) -> 7 | I25: =I24+H25 -> 98 | J25: =ROUND(C25/Parametres!$B$104,0) -> 197 | K25: =ROUND(J25/Parametres!$B$46,1) -> 49.3 | L25: =ROUND(K25/4.345,1) -> 11.3
A26: 22 | B26: =IF(A26=1,0,IF(A26-1<=Parametres!$B$10,ROUND(Parametres!$B$8*(A26-1)^Parametres!$B$9,0),ROUND(Parametres!$B$8*Parametres!$B$10^Parametres!$B$9+Parametres!$B$11*(A26-1-Parametres!$B$10),0))) -> 4812 | C26: =C25+B26 -> 42851 | D26: =Parametres!$B$15+Parametres!$B$16*(A26-1) -> 835 | E26: =Parametres!$B$17+Parametres!$B$18*(A26-1) -> 136 | F26: =Parametres!$B$19+Parametres!$B$20*(A26-1) -> 57.5 | G26: =Parametres!$B$21+Parametres!$B$22*(A26/(A26+Parametres!$B$23)) -> 0.12857143 | H26: =IF(A26=1,0,Parametres!$B$70+Parametres!$B$71*INT(A26/5)) -> 7 | I26: =I25+H26 -> 105 | J26: =ROUND(C26/Parametres!$B$104,0) -> 222 | K26: =ROUND(J26/Parametres!$B$46,1) -> 55.5 | L26: =ROUND(K26/4.345,1) -> 12.8
A27: 23 | B27: =IF(A27=1,0,IF(A27-1<=Parametres!$B$10,ROUND(Parametres!$B$8*(A27-1)^Parametres!$B$9,0),ROUND(Parametres!$B$8*Parametres!$B$10^Parametres!$B$9+Parametres!$B$11*(A27-1-Parametres!$B$10),0))) -> 5159 | C27: =C26+B27 -> 48010 | D27: =Parametres!$B$15+Parametres!$B$16*(A27-1) -> 870 | E27: =Parametres!$B$17+Parametres!$B$18*(A27-1) -> 142 | F27: =Parametres!$B$19+Parametres!$B$20*(A27-1) -> 60 | G27: =Parametres!$B$21+Parametres!$B$22*(A27/(A27+Parametres!$B$23)) -> 0.13023256 | H27: =IF(A27=1,0,Parametres!$B$70+Parametres!$B$71*INT(A27/5)) -> 7 | I27: =I26+H27 -> 112 | J27: =ROUND(C27/Parametres!$B$104,0) -> 249 | K27: =ROUND(J27/Parametres!$B$46,1) -> 62.3 | L27: =ROUND(K27/4.345,1) -> 14.3
A28: 24 | B28: =IF(A28=1,0,IF(A28-1<=Parametres!$B$10,ROUND(Parametres!$B$8*(A28-1)^Parametres!$B$9,0),ROUND(Parametres!$B$8*Parametres!$B$10^Parametres!$B$9+Parametres!$B$11*(A28-1-Parametres!$B$10),0))) -> 5515 | C28: =C27+B28 -> 53525 | D28: =Parametres!$B$15+Parametres!$B$16*(A28-1) -> 905 | E28: =Parametres!$B$17+Parametres!$B$18*(A28-1) -> 148 | F28: =Parametres!$B$19+Parametres!$B$20*(A28-1) -> 62.5 | G28: =Parametres!$B$21+Parametres!$B$22*(A28/(A28+Parametres!$B$23)) -> 0.13181818 | H28: =IF(A28=1,0,Parametres!$B$70+Parametres!$B$71*INT(A28/5)) -> 7 | I28: =I27+H28 -> 119 | J28: =ROUND(C28/Parametres!$B$104,0) -> 277 | K28: =ROUND(J28/Parametres!$B$46,1) -> 69.3 | L28: =ROUND(K28/4.345,1) -> 15.9
A29: 25 | B29: =IF(A29=1,0,IF(A29-1<=Parametres!$B$10,ROUND(Parametres!$B$8*(A29-1)^Parametres!$B$9,0),ROUND(Parametres!$B$8*Parametres!$B$10^Parametres!$B$9+Parametres!$B$11*(A29-1-Parametres!$B$10),0))) -> 5879 | C29: =C28+B29 -> 59404 | D29: =Parametres!$B$15+Parametres!$B$16*(A29-1) -> 940 | E29: =Parametres!$B$17+Parametres!$B$18*(A29-1) -> 154 | F29: =Parametres!$B$19+Parametres!$B$20*(A29-1) -> 65 | G29: =Parametres!$B$21+Parametres!$B$22*(A29/(A29+Parametres!$B$23)) -> 0.13333333 | H29: =IF(A29=1,0,Parametres!$B$70+Parametres!$B$71*INT(A29/5)) -> 8 | I29: =I28+H29 -> 127 | J29: =ROUND(C29/Parametres!$B$104,0) -> 308 | K29: =ROUND(J29/Parametres!$B$46,1) -> 77 | L29: =ROUND(K29/4.345,1) -> 17.7 | M29: Soft cap — la courbe s'aplatit
A30: 26 | B30: =IF(A30=1,0,IF(A30-1<=Parametres!$B$10,ROUND(Parametres!$B$8*(A30-1)^Parametres!$B$9,0),ROUND(Parametres!$B$8*Parametres!$B$10^Parametres!$B$9+Parametres!$B$11*(A30-1-Parametres!$B$10),0))) -> 6250 | C30: =C29+B30 -> 65654 | D30: =Parametres!$B$15+Parametres!$B$16*(A30-1) -> 975 | E30: =Parametres!$B$17+Parametres!$B$18*(A30-1) -> 160 | F30: =Parametres!$B$19+Parametres!$B$20*(A30-1) -> 67.5 | G30: =Parametres!$B$21+Parametres!$B$22*(A30/(A30+Parametres!$B$23)) -> 0.13478261 | H30: =IF(A30=1,0,Parametres!$B$70+Parametres!$B$71*INT(A30/5)) -> 8 | I30: =I29+H30 -> 135 | J30: =ROUND(C30/Parametres!$B$104,0) -> 340 | K30: =ROUND(J30/Parametres!$B$46,1) -> 85 | L30: =ROUND(K30/4.345,1) -> 19.6
A31: 27 | B31: =IF(A31=1,0,IF(A31-1<=Parametres!$B$10,ROUND(Parametres!$B$8*(A31-1)^Parametres!$B$9,0),ROUND(Parametres!$B$8*Parametres!$B$10^Parametres!$B$9+Parametres!$B$11*(A31-1-Parametres!$B$10),0))) -> 6450 | C31: =C30+B31 -> 72104 | D31: =Parametres!$B$15+Parametres!$B$16*(A31-1) -> 1010 | E31: =Parametres!$B$17+Parametres!$B$18*(A31-1) -> 166 | F31: =Parametres!$B$19+Parametres!$B$20*(A31-1) -> 70 | G31: =Parametres!$B$21+Parametres!$B$22*(A31/(A31+Parametres!$B$23)) -> 0.13617021 | H31: =IF(A31=1,0,Parametres!$B$70+Parametres!$B$71*INT(A31/5)) -> 8 | I31: =I30+H31 -> 143 | J31: =ROUND(C31/Parametres!$B$104,0) -> 374 | K31: =ROUND(J31/Parametres!$B$46,1) -> 93.5 | L31: =ROUND(K31/4.345,1) -> 21.5
A32: 28 | B32: =IF(A32=1,0,IF(A32-1<=Parametres!$B$10,ROUND(Parametres!$B$8*(A32-1)^Parametres!$B$9,0),ROUND(Parametres!$B$8*Parametres!$B$10^Parametres!$B$9+Parametres!$B$11*(A32-1-Parametres!$B$10),0))) -> 6650 | C32: =C31+B32 -> 78754 | D32: =Parametres!$B$15+Parametres!$B$16*(A32-1) -> 1045 | E32: =Parametres!$B$17+Parametres!$B$18*(A32-1) -> 172 | F32: =Parametres!$B$19+Parametres!$B$20*(A32-1) -> 72.5 | G32: =Parametres!$B$21+Parametres!$B$22*(A32/(A32+Parametres!$B$23)) -> 0.1375 | H32: =IF(A32=1,0,Parametres!$B$70+Parametres!$B$71*INT(A32/5)) -> 8 | I32: =I31+H32 -> 151 | J32: =ROUND(C32/Parametres!$B$104,0) -> 408 | K32: =ROUND(J32/Parametres!$B$46,1) -> 102 | L32: =ROUND(K32/4.345,1) -> 23.5
A33: 29 | B33: =IF(A33=1,0,IF(A33-1<=Parametres!$B$10,ROUND(Parametres!$B$8*(A33-1)^Parametres!$B$9,0),ROUND(Parametres!$B$8*Parametres!$B$10^Parametres!$B$9+Parametres!$B$11*(A33-1-Parametres!$B$10),0))) -> 6850 | C33: =C32+B33 -> 85604 | D33: =Parametres!$B$15+Parametres!$B$16*(A33-1) -> 1080 | E33: =Parametres!$B$17+Parametres!$B$18*(A33-1) -> 178 | F33: =Parametres!$B$19+Parametres!$B$20*(A33-1) -> 75 | G33: =Parametres!$B$21+Parametres!$B$22*(A33/(A33+Parametres!$B$23)) -> 0.13877551 | H33: =IF(A33=1,0,Parametres!$B$70+Parametres!$B$71*INT(A33/5)) -> 8 | I33: =I32+H33 -> 159 | J33: =ROUND(C33/Parametres!$B$104,0) -> 444 | K33: =ROUND(J33/Parametres!$B$46,1) -> 111 | L33: =ROUND(K33/4.345,1) -> 25.5
A34: 30 | B34: =IF(A34=1,0,IF(A34-1<=Parametres!$B$10,ROUND(Parametres!$B$8*(A34-1)^Parametres!$B$9,0),ROUND(Parametres!$B$8*Parametres!$B$10^Parametres!$B$9+Parametres!$B$11*(A34-1-Parametres!$B$10),0))) -> 7050 | C34: =C33+B34 -> 92654 | D34: =Parametres!$B$15+Parametres!$B$16*(A34-1) -> 1115 | E34: =Parametres!$B$17+Parametres!$B$18*(A34-1) -> 184 | F34: =Parametres!$B$19+Parametres!$B$20*(A34-1) -> 77.5 | G34: =Parametres!$B$21+Parametres!$B$22*(A34/(A34+Parametres!$B$23)) -> 0.14 | H34: =IF(A34=1,0,Parametres!$B$70+Parametres!$B$71*INT(A34/5)) -> 9 | I34: =I33+H34 -> 168 | J34: =ROUND(C34/Parametres!$B$104,0) -> 480 | K34: =ROUND(J34/Parametres!$B$46,1) -> 120 | L34: =ROUND(K34/4.345,1) -> 27.6
A35: 31 | B35: =IF(A35=1,0,IF(A35-1<=Parametres!$B$10,ROUND(Parametres!$B$8*(A35-1)^Parametres!$B$9,0),ROUND(Parametres!$B$8*Parametres!$B$10^Parametres!$B$9+Parametres!$B$11*(A35-1-Parametres!$B$10),0))) -> 7250 | C35: =C34+B35 -> 99904 | D35: =Parametres!$B$15+Parametres!$B$16*(A35-1) -> 1150 | E35: =Parametres!$B$17+Parametres!$B$18*(A35-1) -> 190 | F35: =Parametres!$B$19+Parametres!$B$20*(A35-1) -> 80 | G35: =Parametres!$B$21+Parametres!$B$22*(A35/(A35+Parametres!$B$23)) -> 0.14117647 | H35: =IF(A35=1,0,Parametres!$B$70+Parametres!$B$71*INT(A35/5)) -> 9 | I35: =I34+H35 -> 177 | J35: =ROUND(C35/Parametres!$B$104,0) -> 518 | K35: =ROUND(J35/Parametres!$B$46,1) -> 129.5 | L35: =ROUND(K35/4.345,1) -> 29.8
A36: 32 | B36: =IF(A36=1,0,IF(A36-1<=Parametres!$B$10,ROUND(Parametres!$B$8*(A36-1)^Parametres!$B$9,0),ROUND(Parametres!$B$8*Parametres!$B$10^Parametres!$B$9+Parametres!$B$11*(A36-1-Parametres!$B$10),0))) -> 7450 | C36: =C35+B36 -> 107354 | D36: =Parametres!$B$15+Parametres!$B$16*(A36-1) -> 1185 | E36: =Parametres!$B$17+Parametres!$B$18*(A36-1) -> 196 | F36: =Parametres!$B$19+Parametres!$B$20*(A36-1) -> 82.5 | G36: =Parametres!$B$21+Parametres!$B$22*(A36/(A36+Parametres!$B$23)) -> 0.14230769 | H36: =IF(A36=1,0,Parametres!$B$70+Parametres!$B$71*INT(A36/5)) -> 9 | I36: =I35+H36 -> 186 | J36: =ROUND(C36/Parametres!$B$104,0) -> 556 | K36: =ROUND(J36/Parametres!$B$46,1) -> 139 | L36: =ROUND(K36/4.345,1) -> 32
A37: 33 | B37: =IF(A37=1,0,IF(A37-1<=Parametres!$B$10,ROUND(Parametres!$B$8*(A37-1)^Parametres!$B$9,0),ROUND(Parametres!$B$8*Parametres!$B$10^Parametres!$B$9+Parametres!$B$11*(A37-1-Parametres!$B$10),0))) -> 7650 | C37: =C36+B37 -> 115004 | D37: =Parametres!$B$15+Parametres!$B$16*(A37-1) -> 1220 | E37: =Parametres!$B$17+Parametres!$B$18*(A37-1) -> 202 | F37: =Parametres!$B$19+Parametres!$B$20*(A37-1) -> 85 | G37: =Parametres!$B$21+Parametres!$B$22*(A37/(A37+Parametres!$B$23)) -> 0.14339623 | H37: =IF(A37=1,0,Parametres!$B$70+Parametres!$B$71*INT(A37/5)) -> 9 | I37: =I36+H37 -> 195 | J37: =ROUND(C37/Parametres!$B$104,0) -> 596 | K37: =ROUND(J37/Parametres!$B$46,1) -> 149 | L37: =ROUND(K37/4.345,1) -> 34.3
A38: 34 | B38: =IF(A38=1,0,IF(A38-1<=Parametres!$B$10,ROUND(Parametres!$B$8*(A38-1)^Parametres!$B$9,0),ROUND(Parametres!$B$8*Parametres!$B$10^Parametres!$B$9+Parametres!$B$11*(A38-1-Parametres!$B$10),0))) -> 7850 | C38: =C37+B38 -> 122854 | D38: =Parametres!$B$15+Parametres!$B$16*(A38-1) -> 1255 | E38: =Parametres!$B$17+Parametres!$B$18*(A38-1) -> 208 | F38: =Parametres!$B$19+Parametres!$B$20*(A38-1) -> 87.5 | G38: =Parametres!$B$21+Parametres!$B$22*(A38/(A38+Parametres!$B$23)) -> 0.14444444 | H38: =IF(A38=1,0,Parametres!$B$70+Parametres!$B$71*INT(A38/5)) -> 9 | I38: =I37+H38 -> 204 | J38: =ROUND(C38/Parametres!$B$104,0) -> 637 | K38: =ROUND(J38/Parametres!$B$46,1) -> 159.3 | L38: =ROUND(K38/4.345,1) -> 36.7
A39: 35 | B39: =IF(A39=1,0,IF(A39-1<=Parametres!$B$10,ROUND(Parametres!$B$8*(A39-1)^Parametres!$B$9,0),ROUND(Parametres!$B$8*Parametres!$B$10^Parametres!$B$9+Parametres!$B$11*(A39-1-Parametres!$B$10),0))) -> 8050 | C39: =C38+B39 -> 130904 | D39: =Parametres!$B$15+Parametres!$B$16*(A39-1) -> 1290 | E39: =Parametres!$B$17+Parametres!$B$18*(A39-1) -> 214 | F39: =Parametres!$B$19+Parametres!$B$20*(A39-1) -> 90 | G39: =Parametres!$B$21+Parametres!$B$22*(A39/(A39+Parametres!$B$23)) -> 0.14545455 | H39: =IF(A39=1,0,Parametres!$B$70+Parametres!$B$71*INT(A39/5)) -> 10 | I39: =I38+H39 -> 214 | J39: =ROUND(C39/Parametres!$B$104,0) -> 678 | K39: =ROUND(J39/Parametres!$B$46,1) -> 169.5 | L39: =ROUND(K39/4.345,1) -> 39
A40: 36 | B40: =IF(A40=1,0,IF(A40-1<=Parametres!$B$10,ROUND(Parametres!$B$8*(A40-1)^Parametres!$B$9,0),ROUND(Parametres!$B$8*Parametres!$B$10^Parametres!$B$9+Parametres!$B$11*(A40-1-Parametres!$B$10),0))) -> 8250 | C40: =C39+B40 -> 139154 | D40: =Parametres!$B$15+Parametres!$B$16*(A40-1) -> 1325 | E40: =Parametres!$B$17+Parametres!$B$18*(A40-1) -> 220 | F40: =Parametres!$B$19+Parametres!$B$20*(A40-1) -> 92.5 | G40: =Parametres!$B$21+Parametres!$B$22*(A40/(A40+Parametres!$B$23)) -> 0.14642857 | H40: =IF(A40=1,0,Parametres!$B$70+Parametres!$B$71*INT(A40/5)) -> 10 | I40: =I39+H40 -> 224 | J40: =ROUND(C40/Parametres!$B$104,0) -> 721 | K40: =ROUND(J40/Parametres!$B$46,1) -> 180.3 | L40: =ROUND(K40/4.345,1) -> 41.5
A41: 37 | B41: =IF(A41=1,0,IF(A41-1<=Parametres!$B$10,ROUND(Parametres!$B$8*(A41-1)^Parametres!$B$9,0),ROUND(Parametres!$B$8*Parametres!$B$10^Parametres!$B$9+Parametres!$B$11*(A41-1-Parametres!$B$10),0))) -> 8450 | C41: =C40+B41 -> 147604 | D41: =Parametres!$B$15+Parametres!$B$16*(A41-1) -> 1360 | E41: =Parametres!$B$17+Parametres!$B$18*(A41-1) -> 226 | F41: =Parametres!$B$19+Parametres!$B$20*(A41-1) -> 95 | G41: =Parametres!$B$21+Parametres!$B$22*(A41/(A41+Parametres!$B$23)) -> 0.14736842 | H41: =IF(A41=1,0,Parametres!$B$70+Parametres!$B$71*INT(A41/5)) -> 10 | I41: =I40+H41 -> 234 | J41: =ROUND(C41/Parametres!$B$104,0) -> 765 | K41: =ROUND(J41/Parametres!$B$46,1) -> 191.3 | L41: =ROUND(K41/4.345,1) -> 44
...

Sheet XP Seance
A1: XP SEANCE — comment une vraie seance devient de l'XP
A2: XP brut = XP de base + (volume total / diviseur) + (nb de PR x bonus PR). Puis : XP final = XP brut x mult. nutrition x mult. moral x mult. streak.
A4: POURQUOI CE DECOUPAGE
A5: XP de base | B5: Recompense le fait de se presenter. Empeche qu'une petite seance ne donne rien.
A6: Composante volume | B6: Recompense le travail reel effectue. Impossible a farmer sans lever des charges.
A7: Bonus PR | B7: Recompense le progres, pas la repetition. C'est le lien direct avec la vraie vie.
A8: Multiplicateurs | B8: Nutrition, moral et regularite ne creent jamais d'XP a eux seuls — ils amplifient une seance reelle.
A10: EXEMPLES CHIFFRES — modifie les cellules jaunes pour tester
A11: Type de seance | B11: Volume total (lb) | C11: Nb de PR | D11: XP brut | E11: Mult. nutrition | F11: Mult. moral | G11: Mult. streak | H11: XP final | I11: % du niveau 5
A12: Seance legere / retour de pause | B12: 9000 | C12: 0 | D12: =ROUND(Parametres!$B$5+B12/Parametres!$B$6+C12*Parametres!$B$7,0) -> 95 | E12: 1 | F12: 0.9 | G12: 1 | H12: =ROUND(D12*E12*F12*G12,0) -> 86 | I12: =H12/Progression!$C$9 -> 0.10105758
A13: Seance normale — aucune nutrition loggee | B13: 20000 | C13: 0 | D13: =ROUND(Parametres!$B$5+B13/Parametres!$B$6+C13*Parametres!$B$7,0) -> 150 | E13: 1 | F13: 1 | G13: 1 | H13: =ROUND(D13*E13*F13*G13,0) -> 150 | I13: =H13/Progression!$C$9 -> 0.17626322
A14: Seance normale — nutrition parfaite | B14: 20000 | C14: 0 | D14: =ROUND(Parametres!$B$5+B14/Parametres!$B$6+C14*Parametres!$B$7,0) -> 150 | E14: =1+'Nutrition-Moral'!$C$9 -> 1.17 | F14: 1 | G14: 1 | H14: =ROUND(D14*E14*F14*G14,0) -> 176 | I14: =H14/Progression!$C$9 -> 0.20681551
A15: Seance normale + 1 PR + nutrition parfaite | B15: 20000 | C15: 1 | D15: =ROUND(Parametres!$B$5+B15/Parametres!$B$6+C15*Parametres!$B$7,0) -> 175 | E15: =1+'Nutrition-Moral'!$C$9 -> 1.17 | F15: 1 | G15: 1 | H15: =ROUND(D15*E15*F15*G15,0) -> 205 | I15: =H15/Progression!$C$9 -> 0.24089307
A16: Grosse seance, tout aligne (streak entrainement 10 sem. + serie nutri 15 j) | B16: 30000 | C16: 2 | D16: =ROUND(Parametres!$B$5+B16/Parametres!$B$6+C16*Parametres!$B$7,0) -> 250 | E16: ='Nutrition-Moral'!$D$32 -> 1.32 | F16: 1 | G16: 1.2 | H16: =ROUND(D16*E16*F16*G16,0) -> 396 | I16: =H16/Progression!$C$9 -> 0.4653349
A17: Grosse seance mais moral au plancher | B17: 30000 | C17: 2 | D17: =ROUND(Parametres!$B$5+B17/Parametres!$B$6+C17*Parametres!$B$7,0) -> 250 | E17: 1 | F17: 0.85 | G17: 1 | H17: =ROUND(D17*E17*F17*G17,0) -> 213 | I17: =H17/Progression!$C$9 -> 0.25029377
A19: Lecture : sans nutrition loggee tu restes a 1,00 (aucun malus). Trois cibles + 15 jours de serie = jusqu'a +32% d'XP par seance. Le moral (separe) ne descend jamais sous -15%.
A21: REPERES DE VOLUME REEL (pour calibrer)
A22: Profil de seance | B22: Exercices | C22: Series x reps | D22: Charge moyenne (lb) | E22: Volume total (lb)
A23: Court / accessoire | B23: 5 | C23: 3 x 10 | D23: 60 | E23: =B23*30*D23 -> 9000
A24: Standard haut du corps | B24: 7 | C24: 4 x 8 | D24: 85 | E24: =B24*32*D24 -> 19040
A25: Standard bas du corps | B25: 6 | C25: 4 x 8 | D25: 145 | E25: =B25*32*D25 -> 27840
A26: Longue seance full body | B26: 9 | C26: 4 x 8 | D26: 100 | E26: =B26*32*D26 -> 28800

Sheet Nutrition-Moral
A1: NUTRITION & MORAL — bonus pur, jamais de penalite
A2: La nutrition n'accorde que des bonus. Rien loggee ou cibles ratees = multiplicateur neutre (1,00), jamais de malus. Le moral, lui, ne reagit qu'a l'entrainement reel.
A4: LES 3 CIBLES DU JOUR — chacune independante
A5: Cible | B5: Condition de reussite | C5: Bonus XP si atteinte | D5: Si non atteinte
A6: Calories | B6: Dans +/- 10% de la cible quotidienne (2760 cal) | C6: =Parametres!$B$28 -> 0.05 | D6: Aucun bonus. Jamais de malus.
A7: Proteines | B7: Au moins 90% de la cible (150 g) | C7: =Parametres!$B$29 -> 0.08 | D7: Aucun bonus. Jamais de malus.
A8: Eau | B8: Au moins 90% de la cible (3,1 L) | C8: =Parametres!$B$30 -> 0.04 | D8: Aucun bonus. Jamais de malus.
A9: Maximum cumule (3 cibles le meme jour) | C9: =SUM(C6:C8) -> 0.17
A11: LES 8 COMBINAISONS POSSIBLES D'UNE JOURNEE
A12: Calories | B12: Proteines | C12: Eau | D12: Bonus XP du jour | E12: Nb de cibles atteintes | F12: Compte pour la serie ? (2+)
A13: Oui | B13: Oui | C13: Oui | D13: =Parametres!$B$28+Parametres!$B$29+Parametres!$B$30 -> 0.17 | E13: 3 | F13: OUI
A14: Oui | B14: Oui | C14: Non | D14: =Parametres!$B$28+Parametres!$B$29+0 -> 0.13 | E14: 2 | F14: OUI
A15: Oui | B15: Non | C15: Oui | D15: =Parametres!$B$28+0+Parametres!$B$30 -> 0.09 | E15: 2 | F15: OUI
A16: Oui | B16: Non | C16: Non | D16: =Parametres!$B$28+0+0 -> 0.05 | E16: 1 | F16: non
A17: Non | B17: Oui | C17: Oui | D17: =0+Parametres!$B$29+Parametres!$B$30 -> 0.12 | E17: 2 | F17: OUI
A18: Non | B18: Oui | C18: Non | D18: =0+Parametres!$B$29+0 -> 0.08 | E18: 1 | F18: non
A19: Non | B19: Non | C19: Oui | D19: =0+0+Parametres!$B$30 -> 0.04 | E19: 1 | F19: non
A20: Non | B20: Non | C20: Non | D20: =0+0+0 -> 0 | E20: 0 | F20: non
A21: Ligne du bas (aucune cible) : bonus = 0%, multiplicateur = 1,00. Des 2 cibles sur 3, le jour alimente deja la serie.
A23: LA SERIE (STREAK) — jours parfaits consecutifs
A24: Un jour compte pour la serie des que 2 des 3 cibles sont atteintes (pas besoin des 3). Un jour sous ce seuil — ou non loggue — fait retomber la serie a 0, sans jamais faire descendre le multiplicateur sous 1,00.
A25: Jours parfaits consecutifs | B25: Bonus XP de serie | C25: Chance gagnee | D25: Multiplicateur total (jour parfait + serie)
A26: 0 | B26: =MIN(A26*Parametres!$B$31,Parametres!$B$32) -> 0 | C26: =MIN(A26*Parametres!$B$33,Parametres!$B$34) -> 0 | D26: =1+Parametres!$B$28+Parametres!$B$29+Parametres!$B$30+B26 -> 1.17
A27: 1 | B27: =MIN(A27*Parametres!$B$31,Parametres!$B$32) -> 0.01 | C27: =MIN(A27*Parametres!$B$33,Parametres!$B$34) -> 2 | D27: =1+Parametres!$B$28+Parametres!$B$29+Parametres!$B$30+B27 -> 1.18
A28: 3 | B28: =MIN(A28*Parametres!$B$31,Parametres!$B$32) -> 0.03 | C28: =MIN(A28*Parametres!$B$33,Parametres!$B$34) -> 6 | D28: =1+Parametres!$B$28+Parametres!$B$29+Parametres!$B$30+B28 -> 1.2
A29: 5 | B29: =MIN(A29*Parametres!$B$31,Parametres!$B$32) -> 0.05 | C29: =MIN(A29*Parametres!$B$33,Parametres!$B$34) -> 10 | D29: =1+Parametres!$B$28+Parametres!$B$29+Parametres!$B$30+B29 -> 1.22
A30: 7 | B30: =MIN(A30*Parametres!$B$31,Parametres!$B$32) -> 0.07 | C30: =MIN(A30*Parametres!$B$33,Parametres!$B$34) -> 14 | D30: =1+Parametres!$B$28+Parametres!$B$29+Parametres!$B$30+B30 -> 1.24
A31: 10 | B31: =MIN(A31*Parametres!$B$31,Parametres!$B$32) -> 0.1 | C31: =MIN(A31*Parametres!$B$33,Parametres!$B$34) -> 20 | D31: =1+Parametres!$B$28+Parametres!$B$29+Parametres!$B$30+B31 -> 1.27
A32: 15 | B32: =MIN(A32*Parametres!$B$31,Parametres!$B$32) -> 0.15 | C32: =MIN(A32*Parametres!$B$33,Parametres!$B$34) -> 30 | D32: =1+Parametres!$B$28+Parametres!$B$29+Parametres!$B$30+B32 -> 1.32
A33: 20 | B33: =MIN(A33*Parametres!$B$31,Parametres!$B$32) -> 0.15 | C33: =MIN(A33*Parametres!$B$33,Parametres!$B$34) -> 30 | D33: =1+Parametres!$B$28+Parametres!$B$29+Parametres!$B$30+B33 -> 1.32
A35: A 15 jours de serie et une journee parfaite : multiplicateur de 1,32, soit +32% d'XP sur la seance.
A37: EXEMPLE — UNE SEMAINE TYPE
A38: Jour | B38: 2+ cibles atteintes ? | C38: Serie en cours | D38: Bonus serie | E38: Bonus du jour | F38: Multiplicateur total
A39: Jour 1 | B39: Oui | C39: =IF(B39="Oui",IF(ROW()=39,1,C38+1),0) -> 1 | D39: =MIN(C39*Parametres!$B$31,Parametres!$B$32) -> 0.01 | E39: =IF(B39="Oui",Parametres!$B$28+Parametres!$B$29+Parametres!$B$30,0) -> 0.17 | F39: =1+E39+D39 -> 1.18
A40: Jour 2 | B40: Oui | C40: =IF(B40="Oui",IF(ROW()=39,1,C39+1),0) -> 2 | D40: =MIN(C40*Parametres!$B$31,Parametres!$B$32) -> 0.02 | E40: =IF(B40="Oui",Parametres!$B$28+Parametres!$B$29+Parametres!$B$30,0) -> 0.17 | F40: =1+E40+D40 -> 1.19
A41: Jour 3 | B41: Non | C41: =IF(B41="Oui",IF(ROW()=39,1,C40+1),0) -> 0 | D41: =MIN(C41*Parametres!$B$31,Parametres!$B$32) -> 0 | E41: =IF(B41="Oui",Parametres!$B$28+Parametres!$B$29+Parametres!$B$30,0) -> 0 | F41: =1+E41+D41 -> 1
A42: Jour 4 | B42: Oui | C42: =IF(B42="Oui",IF(ROW()=39,1,C41+1),0) -> 1 | D42: =MIN(C42*Parametres!$B$31,Parametres!$B$32) -> 0.01 | E42: =IF(B42="Oui",Parametres!$B$28+Parametres!$B$29+Parametres!$B$30,0) -> 0.17 | F42: =1+E42+D42 -> 1.18
A43: Jour 5 | B43: Oui | C43: =IF(B43="Oui",IF(ROW()=39,1,C42+1),0) -> 2 | D43: =MIN(C43*Parametres!$B$31,Parametres!$B$32) -> 0.02 | E43: =IF(B43="Oui",Parametres!$B$28+Parametres!$B$29+Parametres!$B$30,0) -> 0.17 | F43: =1+E43+D43 -> 1.19
A44: Jour 6 | B44: Oui | C44: =IF(B44="Oui",IF(ROW()=39,1,C43+1),0) -> 3 | D44: =MIN(C44*Parametres!$B$31,Parametres!$B$32) -> 0.03 | E44: =IF(B44="Oui",Parametres!$B$28+Parametres!$B$29+Parametres!$B$30,0) -> 0.17 | F44: =1+E44+D44 -> 1.2
A45: Jour 7 | B45: Non | C45: =IF(B45="Oui",IF(ROW()=39,1,C44+1),0) -> 0 | D45: =MIN(C45*Parametres!$B$31,Parametres!$B$32) -> 0 | E45: =IF(B45="Oui",Parametres!$B$28+Parametres!$B$29+Parametres!$B$30,0) -> 0 | F45: =1+E45+D45 -> 1
...

Sheet Donjon
A1: DONJON — 10 paliers, le 10e est le boss
A2: Il se resout tout seul, meme hors-ligne (rattrapage au chargement). Echec = retour au palier 1. Chaque cycle complete durcit tout : c'est le mur qui pousse a s'entrainer davantage.
A4: Cycle a afficher | B4: 1 | C4: Cycle 1 = premiere descente. Modifie cette cellule pour voir l'escalade.
A6: Palier | B6: Type | C6: PV ennemi | D6: ATQ ennemi | E6: DEF ennemi | F6: Or largue | G6: Essence | H6: Or cumule (la run) | I6: Essence cumulee
A7: 1 | B7: =IF(A7=Parametres!$B$51,"BOSS","Monstre") -> Monstre | C7: =ROUND(Parametres!$B$52*A7^Parametres!$B$53*(1+Parametres!$B$58)^($B$4-1)*IF(A7=Parametres!$B$51,Parametres!$B$59,1),0) -> 50 | D7: =ROUND(Parametres!$B$54*A7^Parametres!$B$55*(1+Parametres!$B$58)^($B$4-1)*IF(A7=Parametres!$B$51,Parametres!$B$60,1),0) -> 10 | E7: =ROUND(Parametres!$B$56*A7^Parametres!$B$57*(1+Parametres!$B$58)^($B$4-1),0) -> 4 | F7: =ROUND(Parametres!$B$63*A7*(1+Parametres!$B$64*($B$4-1)),0) -> 10 | G7: =Parametres!$B$65+IF(A7=Parametres!$B$51,Parametres!$B$66,0) -> 1 | H7: =F7 -> 10 | I7: =G7 -> 1
A8: 2 | B8: =IF(A8=Parametres!$B$51,"BOSS","Monstre") -> Monstre | C8: =ROUND(Parametres!$B$52*A8^Parametres!$B$53*(1+Parametres!$B$58)^($B$4-1)*IF(A8=Parametres!$B$51,Parametres!$B$59,1),0) -> 93 | D8: =ROUND(Parametres!$B$54*A8^Parametres!$B$55*(1+Parametres!$B$58)^($B$4-1)*IF(A8=Parametres!$B$51,Parametres!$B$60,1),0) -> 17 | E8: =ROUND(Parametres!$B$56*A8^Parametres!$B$57*(1+Parametres!$B$58)^($B$4-1),0) -> 7 | F8: =ROUND(Parametres!$B$63*A8*(1+Parametres!$B$64*($B$4-1)),0) -> 20 | G8: =Parametres!$B$65+IF(A8=Parametres!$B$51,Parametres!$B$66,0) -> 1 | H8: =H7+F8 -> 30 | I8: =I7+G8 -> 2
A9: 3 | B9: =IF(A9=Parametres!$B$51,"BOSS","Monstre") -> Monstre | C9: =ROUND(Parametres!$B$52*A9^Parametres!$B$53*(1+Parametres!$B$58)^($B$4-1)*IF(A9=Parametres!$B$51,Parametres!$B$59,1),0) -> 134 | D9: =ROUND(Parametres!$B$54*A9^Parametres!$B$55*(1+Parametres!$B$58)^($B$4-1)*IF(A9=Parametres!$B$51,Parametres!$B$60,1),0) -> 24 | E9: =ROUND(Parametres!$B$56*A9^Parametres!$B$57*(1+Parametres!$B$58)^($B$4-1),0) -> 10 | F9: =ROUND(Parametres!$B$63*A9*(1+Parametres!$B$64*($B$4-1)),0) -> 30 | G9: =Parametres!$B$65+IF(A9=Parametres!$B$51,Parametres!$B$66,0) -> 1 | H9: =H8+F9 -> 60 | I9: =I8+G9 -> 3
A10: 4 | B10: =IF(A10=Parametres!$B$51,"BOSS","Monstre") -> Monstre | C10: =ROUND(Parametres!$B$52*A10^Parametres!$B$53*(1+Parametres!$B$58)^($B$4-1)*IF(A10=Parametres!$B$51,Parametres!$B$59,1),0) -> 174 | D10: =ROUND(Parametres!$B$54*A10^Parametres!$B$55*(1+Parametres!$B$58)^($B$4-1)*IF(A10=Parametres!$B$51,Parametres!$B$60,1),0) -> 30 | E10: =ROUND(Parametres!$B$56*A10^Parametres!$B$57*(1+Parametres!$B$58)^($B$4-1),0) -> 13 | F10: =ROUND(Parametres!$B$63*A10*(1+Parametres!$B$64*($B$4-1)),0) -> 40 | G10: =Parametres!$B$65+IF(A10=Parametres!$B$51,Parametres!$B$66,0) -> 1 | H10: =H9+F10 -> 100 | I10: =I9+G10 -> 4
A11: 5 | B11: =IF(A11=Parametres!$B$51,"BOSS","Monstre") -> Monstre | C11: =ROUND(Parametres!$B$52*A11^Parametres!$B$53*(1+Parametres!$B$58)^($B$4-1)*IF(A11=Parametres!$B$51,Parametres!$B$59,1),0) -> 213 | D11: =ROUND(Parametres!$B$54*A11^Parametres!$B$55*(1+Parametres!$B$58)^($B$4-1)*IF(A11=Parametres!$B$51,Parametres!$B$60,1),0) -> 36 | E11: =ROUND(Parametres!$B$56*A11^Parametres!$B$57*(1+Parametres!$B$58)^($B$4-1),0) -> 16 | F11: =ROUND(Parametres!$B$63*A11*(1+Parametres!$B$64*($B$4-1)),0) -> 50 | G11: =Parametres!$B$65+IF(A11=Parametres!$B$51,Parametres!$B$66,0) -> 1 | H11: =H10+F11 -> 150 | I11: =I10+G11 -> 5
A12: 6 | B12: =IF(A12=Parametres!$B$51,"BOSS","Monstre") -> Monstre | C12: =ROUND(Parametres!$B$52*A12^Parametres!$B$53*(1+Parametres!$B$58)^($B$4-1)*IF(A12=Parametres!$B$51,Parametres!$B$59,1),0) -> 251 | D12: =ROUND(Parametres!$B$54*A12^Parametres!$B$55*(1+Parametres!$B$58)^($B$4-1)*IF(A12=Parametres!$B$51,Parametres!$B$60,1),0) -> 42 | E12: =ROUND(Parametres!$B$56*A12^Parametres!$B$57*(1+Parametres!$B$58)^($B$4-1),0) -> 18 | F12: =ROUND(Parametres!$B$63*A12*(1+Parametres!$B$64*($B$4-1)),0) -> 60 | G12: =Parametres!$B$65+IF(A12=Parametres!$B$51,Parametres!$B$66,0) -> 1 | H12: =H11+F12 -> 210 | I12: =I11+G12 -> 6
A13: 7 | B13: =IF(A13=Parametres!$B$51,"BOSS","Monstre") -> Monstre | C13: =ROUND(Parametres!$B$52*A13^Parametres!$B$53*(1+Parametres!$B$58)^($B$4-1)*IF(A13=Parametres!$B$51,Parametres!$B$59,1),0) -> 288 | D13: =ROUND(Parametres!$B$54*A13^Parametres!$B$55*(1+Parametres!$B$58)^($B$4-1)*IF(A13=Parametres!$B$51,Parametres!$B$60,1),0) -> 47 | E13: =ROUND(Parametres!$B$56*A13^Parametres!$B$57*(1+Parametres!$B$58)^($B$4-1),0) -> 21 | F13: =ROUND(Parametres!$B$63*A13*(1+Parametres!$B$64*($B$4-1)),0) -> 70 | G13: =Parametres!$B$65+IF(A13=Parametres!$B$51,Parametres!$B$66,0) -> 1 | H13: =H12+F13 -> 280 | I13: =I12+G13 -> 7
A14: 8 | B14: =IF(A14=Parametres!$B$51,"BOSS","Monstre") -> Monstre | C14: =ROUND(Parametres!$B$52*A14^Parametres!$B$53*(1+Parametres!$B$58)^($B$4-1)*IF(A14=Parametres!$B$51,Parametres!$B$59,1),0) -> 325 | D14: =ROUND(Parametres!$B$54*A14^Parametres!$B$55*(1+Parametres!$B$58)^($B$4-1)*IF(A14=Parametres!$B$51,Parametres!$B$60,1),0) -> 53 | E14: =ROUND(Parametres!$B$56*A14^Parametres!$B$57*(1+Parametres!$B$58)^($B$4-1),0) -> 23 | F14: =ROUND(Parametres!$B$63*A14*(1+Parametres!$B$64*($B$4-1)),0) -> 80 | G14: =Parametres!$B$65+IF(A14=Parametres!$B$51,Parametres!$B$66,0) -> 1 | H14: =H13+F14 -> 360 | I14: =I13+G14 -> 8
A15: 9 | B15: =IF(A15=Parametres!$B$51,"BOSS","Monstre") -> Monstre | C15: =ROUND(Parametres!$B$52*A15^Parametres!$B$53*(1+Parametres!$B$58)^($B$4-1)*IF(A15=Parametres!$B$51,Parametres!$B$59,1),0) -> 361 | D15: =ROUND(Parametres!$B$54*A15^Parametres!$B$55*(1+Parametres!$B$58)^($B$4-1)*IF(A15=Parametres!$B$51,Parametres!$B$60,1),0) -> 58 | E15: =ROUND(Parametres!$B$56*A15^Parametres!$B$57*(1+Parametres!$B$58)^($B$4-1),0) -> 26 | F15: =ROUND(Parametres!$B$63*A15*(1+Parametres!$B$64*($B$4-1)),0) -> 90 | G15: =Parametres!$B$65+IF(A15=Parametres!$B$51,Parametres!$B$66,0) -> 1 | H15: =H14+F15 -> 450 | I15: =I14+G15 -> 9
A16: 10 | B16: =IF(A16=Parametres!$B$51,"BOSS","Monstre") -> BOSS | C16: =ROUND(Parametres!$B$52*A16^Parametres!$B$53*(1+Parametres!$B$58)^($B$4-1)*IF(A16=Parametres!$B$51,Parametres!$B$59,1),0) -> 874 | D16: =ROUND(Parametres!$B$54*A16^Parametres!$B$55*(1+Parametres!$B$58)^($B$4-1)*IF(A16=Parametres!$B$51,Parametres!$B$60,1),0) -> 95 | E16: =ROUND(Parametres!$B$56*A16^Parametres!$B$57*(1+Parametres!$B$58)^($B$4-1),0) -> 28 | F16: =ROUND(Parametres!$B$63*A16*(1+Parametres!$B$64*($B$4-1)),0) -> 100 | G16: =Parametres!$B$65+IF(A16=Parametres!$B$51,Parametres!$B$66,0) -> 6 | H16: =H15+F16 -> 550 | I16: =I15+G16 -> 15
A19: ESCALADE DES CYCLES — le boss cycle par cycle
A20: Cycle | B20: PV du boss | C20: ATQ du boss | D20: Or de la run complete | E20: Essence de la run | F20: Difficulte relative | G20: Commentaire
A21: 1 | B21: =ROUND(Parametres!$B$52*Parametres!$B$51^Parametres!$B$53*(1+Parametres!$B$58)^(A21-1)*Parametres!$B$59,0) -> 874 | C21: =ROUND(Parametres!$B$54*Parametres!$B$51^Parametres!$B$55*(1+Parametres!$B$58)^(A21-1)*Parametres!$B$60,0) -> 95 | D21: =ROUND(Parametres!$B$63*55*(1+Parametres!$B$64*(A21-1)),0) -> 550 | E21: =Parametres!$B$65*Parametres!$B$51+Parametres!$B$66 -> 15 | F21: =(1+Parametres!$B$58)^(A21-1) -> 1 | G21: Accessible des le niveau 5.
A22: 2 | B22: =ROUND(Parametres!$B$52*Parametres!$B$51^Parametres!$B$53*(1+Parametres!$B$58)^(A22-1)*Parametres!$B$59,0) -> 1049 | C22: =ROUND(Parametres!$B$54*Parametres!$B$51^Parametres!$B$55*(1+Parametres!$B$58)^(A22-1)*Parametres!$B$60,0) -> 114 | D22: =ROUND(Parametres!$B$63*55*(1+Parametres!$B$64*(A22-1)),0) -> 605 | E22: =Parametres!$B$65*Parametres!$B$51+Parametres!$B$66 -> 15 | F22: =(1+Parametres!$B$58)^(A22-1) -> 1.2
A23: 3 | B23: =ROUND(Parametres!$B$52*Parametres!$B$51^Parametres!$B$53*(1+Parametres!$B$58)^(A23-1)*Parametres!$B$59,0) -> 1258 | C23: =ROUND(Parametres!$B$54*Parametres!$B$51^Parametres!$B$55*(1+Parametres!$B$58)^(A23-1)*Parametres!$B$60,0) -> 136 | D23: =ROUND(Parametres!$B$63*55*(1+Parametres!$B$64*(A23-1)),0) -> 660 | E23: =Parametres!$B$65*Parametres!$B$51+Parametres!$B$66 -> 15 | F23: =(1+Parametres!$B$58)^(A23-1) -> 1.44 | G23: Il faut de l'equipement rare.
A24: 4 | B24: =ROUND(Parametres!$B$52*Parametres!$B$51^Parametres!$B$53*(1+Parametres!$B$58)^(A24-1)*Parametres!$B$59,0) -> 1510 | C24: =ROUND(Parametres!$B$54*Parametres!$B$51^Parametres!$B$55*(1+Parametres!$B$58)^(A24-1)*Parametres!$B$60,0) -> 164 | D24: =ROUND(Parametres!$B$63*55*(1+Parametres!$B$64*(A24-1)),0) -> 715 | E24: =Parametres!$B$65*Parametres!$B$51+Parametres!$B$66 -> 15 | F24: =(1+Parametres!$B$58)^(A24-1) -> 1.728
A25: 5 | B25: =ROUND(Parametres!$B$52*Parametres!$B$51^Parametres!$B$53*(1+Parametres!$B$58)^(A25-1)*Parametres!$B$59,0) -> 1812 | C25: =ROUND(Parametres!$B$54*Parametres!$B$51^Parametres!$B$55*(1+Parametres!$B$58)^(A25-1)*Parametres!$B$60,0) -> 196 | D25: =ROUND(Parametres!$B$63*55*(1+Parametres!$B$64*(A25-1)),0) -> 770 | E25: =Parametres!$B$65*Parametres!$B$51+Parametres!$B$66 -> 15 | F25: =(1+Parametres!$B$58)^(A25-1) -> 2.0736 | G25: Premier vrai palier de patience.
A26: 6 | B26: =ROUND(Parametres!$B$52*Parametres!$B$51^Parametres!$B$53*(1+Parametres!$B$58)^(A26-1)*Parametres!$B$59,0) -> 2174 | C26: =ROUND(Parametres!$B$54*Parametres!$B$51^Parametres!$B$55*(1+Parametres!$B$58)^(A26-1)*Parametres!$B$60,0) -> 236 | D26: =ROUND(Parametres!$B$63*55*(1+Parametres!$B$64*(A26-1)),0) -> 825 | E26: =Parametres!$B$65*Parametres!$B$51+Parametres!$B$66 -> 15 | F26: =(1+Parametres!$B$58)^(A26-1) -> 2.48832
A27: 7 | B27: =ROUND(Parametres!$B$52*Parametres!$B$51^Parametres!$B$53*(1+Parametres!$B$58)^(A27-1)*Parametres!$B$59,0) -> 2609 | C27: =ROUND(Parametres!$B$54*Parametres!$B$51^Parametres!$B$55*(1+Parametres!$B$58)^(A27-1)*Parametres!$B$60,0) -> 283 | D27: =ROUND(Parametres!$B$63*55*(1+Parametres!$B$64*(A27-1)),0) -> 880 | E27: =Parametres!$B$65*Parametres!$B$51+Parametres!$B$66 -> 15 | F27: =(1+Parametres!$B$58)^(A27-1) -> 2.985984
A28: 8 | B28: =ROUND(Parametres!$B$52*Parametres!$B$51^Parametres!$B$53*(1+Parametres!$B$58)^(A28-1)*Parametres!$B$59,0) -> 3131 | C28: =ROUND(Parametres!$B$54*Parametres!$B$51^Parametres!$B$55*(1+Parametres!$B$58)^(A28-1)*Parametres!$B$60,0) -> 339 | D28: =ROUND(Parametres!$B$63*55*(1+Parametres!$B$64*(A28-1)),0) -> 935 | E28: =Parametres!$B$65*Parametres!$B$51+Parametres!$B$66 -> 15 | F28: =(1+Parametres!$B$58)^(A28-1) -> 3.5831808 | G28: Exige de l'epique bien forge.
A29: 9 | B29: =ROUND(Parametres!$B$52*Parametres!$B$51^Parametres!$B$53*(1+Parametres!$B$58)^(A29-1)*Parametres!$B$59,0) -> 3757 | C29: =ROUND(Parametres!$B$54*Parametres!$B$51^Parametres!$B$55*(1+Parametres!$B$58)^(A29-1)*Parametres!$B$60,0) -> 407 | D29: =ROUND(Parametres!$B$63*55*(1+Parametres!$B$64*(A29-1)),0) -> 990 | E29: =Parametres!$B$65*Parametres!$B$51+Parametres!$B$66 -> 15 | F29: =(1+Parametres!$B$58)^(A29-1) -> 4.299817
A30: 10 | B30: =ROUND(Parametres!$B$52*Parametres!$B$51^Parametres!$B$53*(1+Parametres!$B$58)^(A30-1)*Parametres!$B$59,0) -> 4508 | C30: =ROUND(Parametres!$B$54*Parametres!$B$51^Parametres!$B$55*(1+Parametres!$B$58)^(A30-1)*Parametres!$B$60,0) -> 488 | D30: =ROUND(Parametres!$B$63*55*(1+Parametres!$B$64*(A30-1)),0) -> 1045 | E30: =Parametres!$B$65*Parametres!$B$51+Parametres!$B$66 -> 15 | F30: =(1+Parametres!$B$58)^(A30-1) -> 5.1597804
A31: 11 | B31: =ROUND(Parametres!$B$52*Parametres!$B$51^Parametres!$B$53*(1+Parametres!$B$58)^(A31-1)*Parametres!$B$59,0) -> 5410 | C31: =ROUND(Parametres!$B$54*Parametres!$B$51^Parametres!$B$55*(1+Parametres!$B$58)^(A31-1)*Parametres!$B$60,0) -> 586 | D31: =ROUND(Parametres!$B$63*55*(1+Parametres!$B$64*(A31-1)),0) -> 1100 | E31: =Parametres!$B$65*Parametres!$B$51+Parametres!$B$66 -> 15 | F31: =(1+Parametres!$B$58)^(A31-1) -> 6.1917364
A32: 12 | B32: =ROUND(Parametres!$B$52*Parametres!$B$51^Parametres!$B$53*(1+Parametres!$B$58)^(A32-1)*Parametres!$B$59,0) -> 6492 | C32: =ROUND(Parametres!$B$54*Parametres!$B$51^Parametres!$B$55*(1+Parametres!$B$58)^(A32-1)*Parametres!$B$60,0) -> 703 | D32: =ROUND(Parametres!$B$63*55*(1+Parametres!$B$64*(A32-1)),0) -> 1155 | E32: =Parametres!$B$65*Parametres!$B$51+Parametres!$B$66 -> 15 | F32: =(1+Parametres!$B$58)^(A32-1) -> 7.4300837 | G32: Zone de fin de partie.
A33: 13 | B33: =ROUND(Parametres!$B$52*Parametres!$B$51^Parametres!$B$53*(1+Parametres!$B$58)^(A33-1)*Parametres!$B$59,0) -> 7791 | C33: =ROUND(Parametres!$B$54*Parametres!$B$51^Parametres!$B$55*(1+Parametres!$B$58)^(A33-1)*Parametres!$B$60,0) -> 844 | D33: =ROUND(Parametres!$B$63*55*(1+Parametres!$B$64*(A33-1)),0) -> 1210 | E33: =Parametres!$B$65*Parametres!$B$51+Parametres!$B$66 -> 15 | F33: =(1+Parametres!$B$58)^(A33-1) -> 8.9161004
A34: 14 | B34: =ROUND(Parametres!$B$52*Parametres!$B$51^Parametres!$B$53*(1+Parametres!$B$58)^(A34-1)*Parametres!$B$59,0) -> 9349 | C34: =ROUND(Parametres!$B$54*Parametres!$B$51^Parametres!$B$55*(1+Parametres!$B$58)^(A34-1)*Parametres!$B$60,0) -> 1013 | D34: =ROUND(Parametres!$B$63*55*(1+Parametres!$B$64*(A34-1)),0) -> 1265 | E34: =Parametres!$B$65*Parametres!$B$51+Parametres!$B$66 -> 15 | F34: =(1+Parametres!$B$58)^(A34-1) -> 10.699321
A35: 15 | B35: =ROUND(Parametres!$B$52*Parametres!$B$51^Parametres!$B$53*(1+Parametres!$B$58)^(A35-1)*Parametres!$B$59,0) -> 11218 | C35: =ROUND(Parametres!$B$54*Parametres!$B$51^Parametres!$B$55*(1+Parametres!$B$58)^(A35-1)*Parametres!$B$60,0) -> 1215 | D35: =ROUND(Parametres!$B$63*55*(1+Parametres!$B$64*(A35-1)),0) -> 1320 | E35: =Parametres!$B$65*Parametres!$B$51+Parametres!$B$66 -> 15 | F35: =(1+Parametres!$B$58)^(A35-1) -> 12.839185 | G35: Necessite du legendaire + forge max.
A37: Note de design : les PV ne se regenerent PAS entre les paliers d'une meme run. Une descente est donc une gestion de ressource, pas 10 combats independants. C'est ce qui rend l'equipement defensif utile et le boss reellement menacant.
A39: FRONTIERE NIVEAU / CYCLE — quel niveau faut-il pour nettoyer quel cycle
A40: Obtenu par recherche exhaustive sur le modele de combat (equipement moyen du cycle precedent). C'est la table de reference pour verifier que le rythme du donjon suit celui de l'entrainement.
A41: Cycle | B41: Niveau minimum | C41: Semaines estimees (rythme 4 seances) | D41: Niveaux depuis le cycle precedent | E41: Ressenti
A42: 1 | B42: 6 | C42: =INDEX(Progression!$K$5:$K$54,B42) -> 1.8 | D42: =B42 -> 6 | E42: Donjon ouvert. Premieres victoires rapides.
A43: 2 | B43: 7 | C43: =INDEX(Progression!$K$5:$K$54,B43) -> 2.8 | D43: =B43-B42 -> 1 | E43: Un seul niveau d'ecart : ca enchaine.
A44: 3 | B44: 8 | C44: =INDEX(Progression!$K$5:$K$54,B44) -> 4 | D44: =B44-B43 -> 1 | E44: Toujours rapide — c'est la phase d'accroche.
A45: 4 | B45: 10 | C45: =INDEX(Progression!$K$5:$K$54,B45) -> 7.3 | D45: =B45-B44 -> 2 | E45: Premier vrai palier de patience.
A46: 5 | B46: 11 | C46: =INDEX(Progression!$K$5:$K$54,B46) -> 9.3 | D46: =B46-B45 -> 1
...

Sheet Sim Combat
A1: SIMULATEUR DE COMBAT — est-ce que ce niveau passe le donjon ?
A2: Degats = ATQ x (1 - DEF/(DEF+K)). Les PV ne remontent que partiellement entre les paliers (levier de regeneration) : une run est une gestion de ressource, pas 10 combats independants.
A4: ENTREES — modifie les cellules jaunes
A5: Niveau du joueur | B5: 11 | D5: Palier moyen de drop | E5: 8
A6: Cycle du donjon | B6: 5 | D6: Rarete moyenne (1=commun, 2,6=epique) | E6: 1.8
A7: Bonus ATQ de l'equipement | B7: =ROUND((Parametres!$B$86+Parametres!$B$87*$E$5)*$E$6*(1+Parametres!$B$58)^($B$6-1),0) -> 142 | D7: PV par point de puissance | E7: 4.8
A8: Bonus PV de l'equipement | B8: =ROUND((Parametres!$B$86+Parametres!$B$87*$E$5)*$E$6*(1+Parametres!$B$58)^($B$6-1)*$E$7,0) -> 681 | D8: DEF par point de puissance | E8: 0.5
A9: Bonus DEF de l'equipement | B9: =ROUND((Parametres!$B$86+Parametres!$B$87*$E$5)*$E$6*(1+Parametres!$B$58)^($B$6-1)*$E$8,0) -> 71 | D9: L'equipement s'ajuste au cycle choisi. Ecris tes vrais chiffres en B7:B9 pour tester un set precis.
A10: Bonus critique de l'equipement | B10: 0.05 | D10: Bonus critique de l'equipement (bague).
A12: STATS EFFECTIVES DU PERSONNAGE
A13: PV total | B13: =INDEX(Progression!$D$5:$D$54,MATCH($B$5,Progression!$A$5:$A$54,0))+$B$8 -> 1131
A14: ATQ total | B14: =INDEX(Progression!$E$5:$E$54,MATCH($B$5,Progression!$A$5:$A$54,0))+$B$7 -> 212
A15: DEF totale | B15: =INDEX(Progression!$F$5:$F$54,MATCH($B$5,Progression!$A$5:$A$54,0))+$B$9 -> 101
A16: Critique total | B16: =INDEX(Progression!$G$5:$G$54,MATCH($B$5,Progression!$A$5:$A$54,0))+$B$10 -> 0.15322581
A17: Reduction de degats subie | B17: =$B$15/($B$15+Parametres!$B$25) -> 0.55801105
A19: RESOLUTION PALIER PAR PALIER
A20: Palier | B20: PV ennemi | C20: ATQ ennemi | D20: DEF ennemi | E20: Degats par coup | F20: Degats moyens (avec crit) | G20: Tours pour tuer | H20: Degats subis par tour | I20: PV perdus au palier | J20: PV restants | K20: Resultat
